{"activity":"ghpages","category":"activity-error","message":"activity failed with execption:\nTraceback (most recent call last):\n  File \"/Users/sst/anaconda3/envs/dbexample_env/lib/python3.7/site-packages/rever/activity.xsh\", line 83, in __call__\n    self.func(*args, **kwargs)\n  File \"/Users/sst/anaconda3/envs/dbexample_env/lib/python3.7/site-packages/rever/activities/ghpages.xsh\", line 84, in _func\n    git checkout @(branch)\n  File \"/Users/sst/anaconda3/envs/dbexample_env/lib/python3.7/site-packages/xonsh/built_ins.py\", line 1052, in subproc_captured_hiddenobject\n    return run_subproc(cmds, captured=\"hiddenobject\", envs=envs)\n  File \"/Users/sst/anaconda3/envs/dbexample_env/lib/python3.7/site-packages/xonsh/built_ins.py\", line 1011, in run_subproc\n    command.end()\n  File \"/Users/sst/anaconda3/envs/dbexample_env/lib/python3.7/site-packages/xonsh/proc.py\", line 2150, in end\n    self._end(tee_output=tee_output)\n  File \"/Users/sst/anaconda3/envs/dbexample_env/lib/python3.7/site-packages/xonsh/proc.py\", line 2169, in _end\n    self._raise_subproc_error()\n  File \"/Users/sst/anaconda3/envs/dbexample_env/lib/python3.7/site-packages/xonsh/proc.py\", line 2295, in _raise_subproc_error\n    raise subprocess.CalledProcessError(rtn, spec.args, output=self.output)\nsubprocess.CalledProcessError: Command '['git', 'checkout', 'gh-pages']' returned non-zero exit status 1.\nrewinding to 36336538b0a39afeb6303cdf7599d827f632b775","rev":"36336538b0a39afeb6303cdf7599d827f632b775","timestamp":1602279706.738529,"version":"0.1.0"}
{"activity":"ghpages","category":"activity-error","message":"activity failed with execption:\nTraceback (most recent call last):\n  File \"/Users/sst/anaconda3/envs/dbexample_env/lib/python3.7/site-packages/rever/activity.xsh\", line 83, in __call__\n    self.func(*args, **kwargs)\n  File \"/Users/sst/anaconda3/envs/dbexample_env/lib/python3.7/site-packages/rever/activities/ghpages.xsh\", line 84, in _func\n    git checkout @(branch)\n  File \"/Users/sst/anaconda3/envs/dbexample_env/lib/python3.7/site-packages/xonsh/built_ins.py\", line 1052, in subproc_captured_hiddenobject\n    return run_subproc(cmds, captured=\"hiddenobject\", envs=envs)\n  File \"/Users/sst/anaconda3/envs/dbexample_env/lib/python3.7/site-packages/xonsh/built_ins.py\", line 1011, in run_subproc\n    command.end()\n  File \"/Users/sst/anaconda3/envs/dbexample_env/lib/python3.7/site-packages/xonsh/proc.py\", line 2150, in end\n    self._end(tee_output=tee_output)\n  File \"/Users/sst/anaconda3/envs/dbexample_env/lib/python3.7/site-packages/xonsh/proc.py\", line 2169, in _end\n    self._raise_subproc_error()\n  File \"/Users/sst/anaconda3/envs/dbexample_env/lib/python3.7/site-packages/xonsh/proc.py\", line 2295, in _raise_subproc_error\n    raise subprocess.CalledProcessError(rtn, spec.args, output=self.output)\nsubprocess.CalledProcessError: Command '['git', 'checkout', 'gh-pages']' returned non-zero exit status 1.\nrewinding to 36336538b0a39afeb6303cdf7599d827f632b775","rev":"36336538b0a39afeb6303cdf7599d827f632b775","timestamp":1602279807.125035,"version":"0.1.0"}
{"activity":"ghpages","category":"activity-error","message":"activity failed with execption:\nTraceback (most recent call last):\n  File \"/Users/sst/anaconda3/envs/dbexample_env/lib/python3.7/site-packages/rever/activity.xsh\", line 83, in __call__\n    self.func(*args, **kwargs)\n  File \"/Users/sst/anaconda3/envs/dbexample_env/lib/python3.7/site-packages/rever/activities/ghpages.xsh\", line 84, in _func\n    git checkout @(branch)\n  File \"/Users/sst/anaconda3/envs/dbexample_env/lib/python3.7/site-packages/xonsh/built_ins.py\", line 1052, in subproc_captured_hiddenobject\n    return run_subproc(cmds, captured=\"hiddenobject\", envs=envs)\n  File \"/Users/sst/anaconda3/envs/dbexample_env/lib/python3.7/site-packages/xonsh/built_ins.py\", line 1011, in run_subproc\n    command.end()\n  File \"/Users/sst/anaconda3/envs/dbexample_env/lib/python3.7/site-packages/xonsh/proc.py\", line 2150, in end\n    self._end(tee_output=tee_output)\n  File \"/Users/sst/anaconda3/envs/dbexample_env/lib/python3.7/site-packages/xonsh/proc.py\", line 2169, in _end\n    self._raise_subproc_error()\n  File \"/Users/sst/anaconda3/envs/dbexample_env/lib/python3.7/site-packages/xonsh/proc.py\", line 2295, in _raise_subproc_error\n    raise subprocess.CalledProcessError(rtn, spec.args, output=self.output)\nsubprocess.CalledProcessError: Command '['git', 'checkout', 'gh-pages']' returned non-zero exit status 1.\nrewinding to 36336538b0a39afeb6303cdf7599d827f632b775","rev":"36336538b0a39afeb6303cdf7599d827f632b775","timestamp":1602279830.858072,"version":"0.1.0"}
{"activity":"ghpages","category":"activity-error","message":"activity failed with execption:\nTraceback (most recent call last):\n  File \"/Users/sst/anaconda3/envs/dbexample_env/lib/python3.7/site-packages/rever/activity.xsh\", line 83, in __call__\n    self.func(*args, **kwargs)\n  File \"/Users/sst/anaconda3/envs/dbexample_env/lib/python3.7/site-packages/rever/activities/ghpages.xsh\", line 84, in _func\n    git checkout @(branch)\n  File \"/Users/sst/anaconda3/envs/dbexample_env/lib/python3.7/site-packages/xonsh/built_ins.py\", line 1052, in subproc_captured_hiddenobject\n    return run_subproc(cmds, captured=\"hiddenobject\", envs=envs)\n  File \"/Users/sst/anaconda3/envs/dbexample_env/lib/python3.7/site-packages/xonsh/built_ins.py\", line 1011, in run_subproc\n    command.end()\n  File \"/Users/sst/anaconda3/envs/dbexample_env/lib/python3.7/site-packages/xonsh/proc.py\", line 2150, in end\n    self._end(tee_output=tee_output)\n  File \"/Users/sst/anaconda3/envs/dbexample_env/lib/python3.7/site-packages/xonsh/proc.py\", line 2169, in _end\n    self._raise_subproc_error()\n  File \"/Users/sst/anaconda3/envs/dbexample_env/lib/python3.7/site-packages/xonsh/proc.py\", line 2295, in _raise_subproc_error\n    raise subprocess.CalledProcessError(rtn, spec.args, output=self.output)\nsubprocess.CalledProcessError: Command '['git', 'checkout', 'gh-pages']' returned non-zero exit status 1.\nrewinding to fe8157ce76998db90f9f77768d8b2ddcb364e86e","rev":"36336538b0a39afeb6303cdf7599d827f632b775","timestamp":1602279946.907813,"version":"0.1.0"}
{"activity":"ghpages","category":"activity-error","message":"activity failed with execption:\nTraceback (most recent call last):\n  File \"/Users/sst/anaconda3/envs/dbexample_env/lib/python3.7/site-packages/rever/activity.xsh\", line 83, in __call__\n    self.func(*args, **kwargs)\n  File \"/Users/sst/anaconda3/envs/dbexample_env/lib/python3.7/site-packages/rever/activities/ghpages.xsh\", line 84, in _func\n    git checkout @(branch)\n  File \"/Users/sst/anaconda3/envs/dbexample_env/lib/python3.7/site-packages/xonsh/built_ins.py\", line 1052, in subproc_captured_hiddenobject\n    return run_subproc(cmds, captured=\"hiddenobject\", envs=envs)\n  File \"/Users/sst/anaconda3/envs/dbexample_env/lib/python3.7/site-packages/xonsh/built_ins.py\", line 1011, in run_subproc\n    command.end()\n  File \"/Users/sst/anaconda3/envs/dbexample_env/lib/python3.7/site-packages/xonsh/proc.py\", line 2150, in end\n    self._end(tee_output=tee_output)\n  File \"/Users/sst/anaconda3/envs/dbexample_env/lib/python3.7/site-packages/xonsh/proc.py\", line 2169, in _end\n    self._raise_subproc_error()\n  File \"/Users/sst/anaconda3/envs/dbexample_env/lib/python3.7/site-packages/xonsh/proc.py\", line 2295, in _raise_subproc_error\n    raise subprocess.CalledProcessError(rtn, spec.args, output=self.output)\nsubprocess.CalledProcessError: Command '['git', 'checkout', 'gh-pages']' returned non-zero exit status 1.\nrewinding to fe8157ce76998db90f9f77768d8b2ddcb364e86e","rev":"36336538b0a39afeb6303cdf7599d827f632b775","timestamp":1602280019.4414349,"version":"0.1.0"}
{"activity":"ghpages","category":"activity-error","message":"activity failed with execption:\nTraceback (most recent call last):\n  File \"/Users/sst/anaconda3/envs/dbexample_env/lib/python3.7/site-packages/rever/activity.xsh\", line 83, in __call__\n    self.func(*args, **kwargs)\n  File \"/Users/sst/anaconda3/envs/dbexample_env/lib/python3.7/site-packages/rever/activities/ghpages.xsh\", line 84, in _func\n    git checkout @(branch)\n  File \"/Users/sst/anaconda3/envs/dbexample_env/lib/python3.7/site-packages/xonsh/built_ins.py\", line 1052, in subproc_captured_hiddenobject\n    return run_subproc(cmds, captured=\"hiddenobject\", envs=envs)\n  File \"/Users/sst/anaconda3/envs/dbexample_env/lib/python3.7/site-packages/xonsh/built_ins.py\", line 1011, in run_subproc\n    command.end()\n  File \"/Users/sst/anaconda3/envs/dbexample_env/lib/python3.7/site-packages/xonsh/proc.py\", line 2150, in end\n    self._end(tee_output=tee_output)\n  File \"/Users/sst/anaconda3/envs/dbexample_env/lib/python3.7/site-packages/xonsh/proc.py\", line 2169, in _end\n    self._raise_subproc_error()\n  File \"/Users/sst/anaconda3/envs/dbexample_env/lib/python3.7/site-packages/xonsh/proc.py\", line 2295, in _raise_subproc_error\n    raise subprocess.CalledProcessError(rtn, spec.args, output=self.output)\nsubprocess.CalledProcessError: Command '['git', 'checkout', 'gh-pages']' returned non-zero exit status 1.\nrewinding to 988274f03b20530848599d043b7210f6ea4e909f","rev":"36336538b0a39afeb6303cdf7599d827f632b775","timestamp":1602284199.79773,"version":"0.1.1"}
